<sdf version='1.6'>
  <world name='default'>
    <scene>
      <shadows>0</shadows>
      <ambient>0.4 0.4 0.4 1</ambient>
      <background>0.7 0.7 0.7 1</background>
    </scene>
    <gui fullscreen='0'>
      <camera name='user_camera'>
        <pose frame=''>3.72243 -0.858563 7.25399 0 1.0395 2.65</pose>
        <view_controller>orbit</view_controller>
        <projection_type>perspective</projection_type>
      </camera>
    </gui>
    <light name='sun' type='directional'>
      <cast_shadows>1</cast_shadows>
      <pose frame=''>0 0 10 0 -0 0</pose>
      <diffuse>0.8 0.8 0.8 1</diffuse>
      <specular>0.2 0.2 0.2 1</specular>
      <attenuation>
        <range>1000</range>
        <constant>0.9</constant>
        <linear>0.01</linear>
        <quadratic>0.001</quadratic>
      </attenuation>
      <direction>-0.5 0.1 -0.9</direction>
    </light>
    <model name='ground_plane'>
      <static>1</static>
      <link name='link'>
        <collision name='collision'>
          <geometry>
            <plane>
              <normal>0 0 1</normal>
              <size>100 100</size>
            </plane>
          </geometry>
          <surface>
            <contact>
              <collide_bitmask>65535</collide_bitmask>
              <ode/>
            </contact>
            <friction>
              <ode>
                <mu>100</mu>
                <mu2>50</mu2>
              </ode>
              <torsional>
                <ode/>
              </torsional>
            </friction>
            <bounce/>
          </surface>
          <max_contacts>10</max_contacts>
        </collision>
        <visual name='visual'>
          <cast_shadows>0</cast_shadows>
          <geometry>
            <plane>
              <normal>0 0 1</normal>
              <size>100 100</size>
            </plane>
          </geometry>
          <material>
            <script>
              <uri>file://media/materials/scripts/gazebo.material</uri>
              <name>Gazebo/Grey</name>
            </script>
          </material>
        </visual>
        <self_collide>0</self_collide>
        <enable_wind>0</enable_wind>
        <kinematic>0</kinematic>
      </link>
    </model>
    <gravity>0 0 -9.8</gravity>
    <magnetic_field>6e-06 2.3e-05 -4.2e-05</magnetic_field>
    <atmosphere type='adiabatic'/>
    <physics name='default_physics' default='0' type='ode'>
      <max_step_size>0.001</max_step_size>
      <real_time_factor>1</real_time_factor>
      <real_time_update_rate>1000</real_time_update_rate>
    </physics>
    <audio>
      <device>default</device>
    </audio>
    <wind/>
    <spherical_coordinates>
      <surface_model>EARTH_WGS84</surface_model>
      <latitude_deg>0</latitude_deg>
      <longitude_deg>0</longitude_deg>
      <elevation>0</elevation>
      <heading_deg>0</heading_deg>
    </spherical_coordinates>
    <model name='tr2'>
      <link name='base_link'>
        <pose frame=''>0 0 0 0 -0 0</pose>
        <inertial>
          <pose frame=''>0 0 0 0 -0 0</pose>
          <mass>1</mass>
          <inertia>
            <ixx>0.1</ixx>
            <ixy>0</ixy>
            <ixz>0</ixz>
            <iyy>0.1</iyy>
            <iyz>0</iyz>
            <izz>0.1</izz>
          </inertia>
        </inertial>
        <collision name='base_link_collision'>
          <pose frame=''>0 0 0 0 -0 1.5708</pose>
          <geometry>
            <mesh>
              <scale>0.001 0.001 0.001</scale>
              <uri>/home/zach/ros_ws/src/tr2_essentials/tr2_description/meshes/stl/link_b0.stl</uri>
            </mesh>
          </geometry>
          <surface>
            <contact>
              <ode/>
            </contact>
            <friction>
              <ode/>
              <torsional>
                <ode/>
              </torsional>
            </friction>
            <bounce/>
          </surface>
          <max_contacts>10</max_contacts>
        </collision>
        <visual name='base_link_visual'>
          <pose frame=''>0 0 0 0 -0 1.5708</pose>
          <geometry>
            <mesh>
              <scale>0.001 0.001 0.001</scale>
              <uri>/home/zach/ros_ws/src/tr2_essentials/tr2_description/meshes/stl/link_b0.stl</uri>
            </mesh>
          </geometry>
          <material>
            <script>
              <name>Gazebo/DarkGrey</name>
              <uri>file://media/materials/scripts/gazebo.material</uri>
            </script>
          </material>
        </visual>
        <gravity>1</gravity>
        <velocity_decay/>
        <self_collide>0</self_collide>
        <enable_wind>0</enable_wind>
        <kinematic>0</kinematic>
      </link>
      <link name='link_a0'>
        <pose frame=''>0.0933 0.1282 0.7292 3.14159 9.3e-05 3.14159</pose>
        <inertial>
          <pose frame=''>0 0 0 0 -0 0</pose>
          <mass>0.005</mass>
          <inertia>
            <ixx>0.001</ixx>
            <ixy>0</ixy>
            <ixz>0</ixz>
            <iyy>0.001</iyy>
            <iyz>0</iyz>
            <izz>0.001</izz>
          </inertia>
        </inertial>
        <collision name='link_a0_collision'>
          <pose frame=''>0 0 0 3.1415 -0 1.5708</pose>
          <geometry>
            <mesh>
              <scale>0.001 0.001 0.001</scale>
              <uri>/home/zach/ros_ws/src/tr2_essentials/tr2_description/meshes/stl/link_a0.stl</uri>
            </mesh>
          </geometry>
          <surface>
            <contact>
              <ode/>
            </contact>
            <friction>
              <ode/>
              <torsional>
                <ode/>
              </torsional>
            </friction>
            <bounce/>
          </surface>
          <max_contacts>10</max_contacts>
        </collision>
        <visual name='link_a0_visual'>
          <pose frame=''>0 0 0 3.1415 -0 1.5708</pose>
          <geometry>
            <mesh>
              <scale>0.001 0.001 0.001</scale>
              <uri>/home/zach/ros_ws/src/tr2_essentials/tr2_description/meshes/stl/link_a0.stl</uri>
            </mesh>
          </geometry>
          <material>
            <script>
              <name>Gazebo/DarkGrey</name>
              <uri>file://media/materials/scripts/gazebo.material</uri>
            </script>
          </material>
        </visual>
        <gravity>1</gravity>
        <velocity_decay/>
        <self_collide>0</self_collide>
        <enable_wind>0</enable_wind>
        <kinematic>0</kinematic>
      </link>
      <joint name='a0' type='revolute'>
        <child>link_a0</child>
        <parent>base_link</parent>
        <axis>
          <xyz>9.3e-05 0 -1</xyz>
          <limit>
            <lower>-2</lower>
            <upper>2</upper>
            <effort>100</effort>
            <velocity>0.2</velocity>
          </limit>
          <dynamics>
            <damping>0.1</damping>
            <friction>0.1</friction>
            <spring_reference>0</spring_reference>
            <spring_stiffness>0</spring_stiffness>
          </dynamics>
          <use_parent_model_frame>1</use_parent_model_frame>
        </axis>
      </joint>
      <link name='link_a1'>
        <pose frame=''>-0.121308 0.2082 0.81888 3.1415 1.57071 -4e-06</pose>
        <inertial>
          <pose frame=''>0 0 0 0 -0 0</pose>
          <mass>0.005</mass>
          <inertia>
            <ixx>0.001</ixx>
            <ixy>0</ixy>
            <ixz>0</ixz>
            <iyy>0.001</iyy>
            <iyz>0</iyz>
            <izz>0.001</izz>
          </inertia>
        </inertial>
        <collision name='link_a1_collision'>
          <pose frame=''>0 0 0 -3.14159 1.57079 1.57079</pose>
          <geometry>
            <mesh>
              <scale>0.001 0.001 0.001</scale>
              <uri>/home/zach/ros_ws/src/tr2_essentials/tr2_description/meshes/stl/link_a1.stl</uri>
            </mesh>
          </geometry>
          <surface>
            <contact>
              <ode/>
            </contact>
            <friction>
              <ode/>
              <torsional>
                <ode/>
              </torsional>
            </friction>
            <bounce/>
          </surface>
          <max_contacts>10</max_contacts>
        </collision>
        <visual name='link_a1_visual'>
          <pose frame=''>0 0 0 -3.14159 1.57079 1.57079</pose>
          <geometry>
            <mesh>
              <scale>0.001 0.001 0.001</scale>
              <uri>/home/zach/ros_ws/src/tr2_essentials/tr2_description/meshes/stl/link_a1.stl</uri>
            </mesh>
          </geometry>
          <material>
            <script>
              <name>Gazebo/DarkGrey</name>
              <uri>file://media/materials/scripts/gazebo.material</uri>
            </script>
          </material>
        </visual>
        <gravity>1</gravity>
        <velocity_decay/>
        <self_collide>0</self_collide>
        <enable_wind>0</enable_wind>
        <kinematic>0</kinematic>
      </link>
      <joint name='a1' type='revolute'>
        <child>link_a1</child>
        <parent>link_a0</parent>
        <axis>
          <xyz>9.3e-05 -1 0</xyz>
          <limit>
            <lower>-15</lower>
            <upper>15</upper>
            <effort>100</effort>
            <velocity>0.2</velocity>
          </limit>
          <dynamics>
            <damping>0.1</damping>
            <friction>0.1</friction>
            <spring_reference>0</spring_reference>
            <spring_stiffness>0</spring_stiffness>
          </dynamics>
          <use_parent_model_frame>1</use_parent_model_frame>
        </axis>
      </joint>
      <link name='link_a2'>
        <pose frame=''>-0.121304 0.3179 0.65198 -0.00243 -1.57079 0.00243</pose>
        <inertial>
          <pose frame=''>0 0 0 0 -0 0</pose>
          <mass>0.005</mass>
          <inertia>
            <ixx>0.001</ixx>
            <ixy>0</ixy>
            <ixz>0</ixz>
            <iyy>0.001</iyy>
            <iyz>0</iyz>
            <izz>0.001</izz>
          </inertia>
        </inertial>
        <collision name='link_a2_collision'>
          <pose frame=''>0 0 0 1.5708 0 -1.5708</pose>
          <geometry>
            <mesh>
              <scale>0.001 0.001 0.001</scale>
              <uri>/home/zach/ros_ws/src/tr2_essentials/tr2_description/meshes/stl/link_a2.stl</uri>
            </mesh>
          </geometry>
          <surface>
            <contact>
              <ode/>
            </contact>
            <friction>
              <ode/>
              <torsional>
                <ode/>
              </torsional>
            </friction>
            <bounce/>
          </surface>
          <max_contacts>10</max_contacts>
        </collision>
        <visual name='link_a2_visual'>
          <pose frame=''>0 0 0 1.5708 0 -1.5708</pose>
          <geometry>
            <mesh>
              <scale>0.001 0.001 0.001</scale>
              <uri>/home/zach/ros_ws/src/tr2_essentials/tr2_description/meshes/stl/link_a2.stl</uri>
            </mesh>
          </geometry>
          <material>
            <script>
              <name>Gazebo/DarkGrey</name>
              <uri>file://media/materials/scripts/gazebo.material</uri>
            </script>
          </material>
        </visual>
        <gravity>1</gravity>
        <velocity_decay/>
        <self_collide>0</self_collide>
        <enable_wind>0</enable_wind>
        <kinematic>0</kinematic>
      </link>
      <joint name='a2' type='revolute'>
        <child>link_a2</child>
        <parent>link_a1</parent>
        <axis>
          <xyz>4e-06 0 1</xyz>
          <limit>
            <lower>-15</lower>
            <upper>15</upper>
            <effort>100</effort>
            <velocity>0.2</velocity>
          </limit>
          <dynamics>
            <damping>0.1</damping>
            <friction>0.1</friction>
            <spring_reference>0</spring_reference>
            <spring_stiffness>0</spring_stiffness>
          </dynamics>
          <use_parent_model_frame>1</use_parent_model_frame>
        </axis>
      </joint>
      <link name='link_a3'>
        <pose frame=''>-0.121304 0.2379 0.49758 0 7e-06 0</pose>
        <inertial>
          <pose frame=''>0 0 0 0 -0 0</pose>
          <mass>0.005</mass>
          <inertia>
            <ixx>0.001</ixx>
            <ixy>0</ixy>
            <ixz>0</ixz>
            <iyy>0.001</iyy>
            <iyz>0</iyz>
            <izz>0.001</izz>
          </inertia>
        </inertial>
        <collision name='link_a3_collision'>
          <pose frame=''>0 0 0 -3.14159 1.57079 1.57079</pose>
          <geometry>
            <mesh>
              <scale>0.001 0.001 0.001</scale>
              <uri>/home/zach/ros_ws/src/tr2_essentials/tr2_description/meshes/stl/link_a3.stl</uri>
            </mesh>
          </geometry>
          <surface>
            <contact>
              <ode/>
            </contact>
            <friction>
              <ode/>
              <torsional>
                <ode/>
              </torsional>
            </friction>
            <bounce/>
          </surface>
          <max_contacts>10</max_contacts>
        </collision>
        <visual name='link_a3_visual'>
          <pose frame=''>0 0 0 -3.14159 1.57079 1.57079</pose>
          <geometry>
            <mesh>
              <scale>0.001 0.001 0.001</scale>
              <uri>/home/zach/ros_ws/src/tr2_essentials/tr2_description/meshes/stl/link_a3.stl</uri>
            </mesh>
          </geometry>
          <material>
            <script>
              <name>Gazebo/DarkGrey</name>
              <uri>file://media/materials/scripts/gazebo.material</uri>
            </script>
          </material>
        </visual>
        <gravity>1</gravity>
        <velocity_decay/>
        <self_collide>0</self_collide>
        <enable_wind>0</enable_wind>
        <kinematic>0</kinematic>
      </link>
      <joint name='a3' type='revolute'>
        <child>link_a3</child>
        <parent>link_a2</parent>
        <axis>
          <xyz>0 1 -0</xyz>
          <limit>
            <lower>-15</lower>
            <upper>15</upper>
            <effort>100</effort>
            <velocity>0.2</velocity>
          </limit>
          <dynamics>
            <damping>0.1</damping>
            <friction>0.1</friction>
            <spring_reference>0</spring_reference>
            <spring_stiffness>0</spring_stiffness>
          </dynamics>
          <use_parent_model_frame>1</use_parent_model_frame>
        </axis>
      </joint>
      <link name='link_g0'>
        <pose frame=''>0.045596 0.1282 0.497579 -2.61799 8.5e-05 -3.14159</pose>
        <inertial>
          <pose frame=''>0 0 0 0 -0 0</pose>
          <mass>0.005</mass>
          <inertia>
            <ixx>0.001</ixx>
            <ixy>0</ixy>
            <ixz>0</ixz>
            <iyy>0.001</iyy>
            <iyz>0</iyz>
            <izz>0.001</izz>
          </inertia>
        </inertial>
        <collision name='link_g0_collision'>
          <pose frame=''>0 0 0 1.5708 0 -1.5708</pose>
          <geometry>
            <mesh>
              <scale>0.001 0.001 0.001</scale>
              <uri>/home/zach/ros_ws/src/tr2_essentials/tr2_description/meshes/stl/link_g0.stl</uri>
            </mesh>
          </geometry>
          <surface>
            <contact>
              <ode/>
            </contact>
            <friction>
              <ode/>
              <torsional>
                <ode/>
              </torsional>
            </friction>
            <bounce/>
          </surface>
          <max_contacts>10</max_contacts>
        </collision>
        <visual name='link_g0_visual'>
          <pose frame=''>0 0 0 1.5708 0 -1.5708</pose>
          <geometry>
            <mesh>
              <scale>0.001 0.001 0.001</scale>
              <uri>/home/zach/ros_ws/src/tr2_essentials/tr2_description/meshes/stl/link_g0.stl</uri>
            </mesh>
          </geometry>
          <material>
            <script>
              <name>Gazebo/DarkGrey</name>
              <uri>file://media/materials/scripts/gazebo.material</uri>
            </script>
          </material>
        </visual>
        <gravity>1</gravity>
        <velocity_decay/>
        <self_collide>0</self_collide>
        <enable_wind>0</enable_wind>
        <kinematic>0</kinematic>
      </link>
      <joint name='a4' type='revolute'>
        <child>link_g0</child>
        <parent>link_a3</parent>
        <axis>
          <xyz>-1 -0 -8.5e-05</xyz>
          <limit>
            <lower>-15</lower>
            <upper>15</upper>
            <effort>100</effort>
            <velocity>0.2</velocity>
          </limit>
          <dynamics>
            <damping>0.1</damping>
            <friction>0.1</friction>
            <spring_reference>0</spring_reference>
            <spring_stiffness>0</spring_stiffness>
          </dynamics>
          <use_parent_model_frame>1</use_parent_model_frame>
        </axis>
      </joint>
      <link name='link_g1'>
        <pose frame=''>0.180596 0.134695 0.49384 -2.61799 8.5e-05 -3.14159</pose>
        <inertial>
          <pose frame=''>0 0 0 0 -0 0</pose>
          <mass>0.005</mass>
          <inertia>
            <ixx>0.001</ixx>
            <ixy>0</ixy>
            <ixz>0</ixz>
            <iyy>0.001</iyy>
            <iyz>0</iyz>
            <izz>0.001</izz>
          </inertia>
        </inertial>
        <collision name='link_g1_collision'>
          <pose frame=''>0 0 0 -3.14159 -1.57079 -1.57079</pose>
          <geometry>
            <mesh>
              <scale>0.001 0.001 0.001</scale>
              <uri>/home/zach/ros_ws/src/tr2_essentials/tr2_description/meshes/stl/link_g1.stl</uri>
            </mesh>
          </geometry>
          <surface>
            <contact>
              <ode/>
            </contact>
            <friction>
              <ode/>
              <torsional>
                <ode/>
              </torsional>
            </friction>
            <bounce/>
          </surface>
          <max_contacts>10</max_contacts>
        </collision>
        <visual name='link_g1_visual'>
          <pose frame=''>0 0 0 -3.14159 -1.57079 -1.57079</pose>
          <geometry>
            <mesh>
              <scale>0.001 0.001 0.001</scale>
              <uri>/home/zach/ros_ws/src/tr2_essentials/tr2_description/meshes/stl/link_g1.stl</uri>
            </mesh>
          </geometry>
          <material>
            <script>
              <name>Gazebo/DarkGrey</name>
              <uri>file://media/materials/scripts/gazebo.material</uri>
            </script>
          </material>
        </visual>
        <gravity>1</gravity>
        <velocity_decay/>
        <self_collide>0</self_collide>
        <enable_wind>0</enable_wind>
        <kinematic>0</kinematic>
      </link>
      <joint name='g0' type='prismatic'>
        <child>link_g1</child>
        <parent>link_g0</parent>
        <axis>
          <xyz>4.3e-05 0.866025 -0.500001</xyz>
          <limit>
            <lower>0</lower>
            <upper>0.041</upper>
            <effort>100</effort>
            <velocity>0.01</velocity>
          </limit>
          <dynamics>
            <damping>0.1</damping>
            <friction>0.1</friction>
            <spring_reference>0</spring_reference>
            <spring_stiffness>0</spring_stiffness>
          </dynamics>
          <use_parent_model_frame>1</use_parent_model_frame>
        </axis>
      </joint>
      <link name='link_g1_b'>
        <pose frame=''>0.180595 0.121705 0.50134 -2.61799 8.5e-05 -3.14159</pose>
        <inertial>
          <pose frame=''>0 0 0 0 -0 0</pose>
          <mass>0.005</mass>
          <inertia>
            <ixx>0.001</ixx>
            <ixy>0</ixy>
            <ixz>0</ixz>
            <iyy>0.001</iyy>
            <iyz>0</iyz>
            <izz>0.001</izz>
          </inertia>
        </inertial>
        <collision name='link_g1_b_collision'>
          <pose frame=''>0 0 0 -3.14159 -1.57079 -1.57079</pose>
          <geometry>
            <mesh>
              <scale>0.001 0.001 0.001</scale>
              <uri>/home/zach/ros_ws/src/tr2_essentials/tr2_description/meshes/stl/link_g1_b.stl</uri>
            </mesh>
          </geometry>
          <surface>
            <contact>
              <ode/>
            </contact>
            <friction>
              <ode/>
              <torsional>
                <ode/>
              </torsional>
            </friction>
            <bounce/>
          </surface>
          <max_contacts>10</max_contacts>
        </collision>
        <visual name='link_g1_b_visual'>
          <pose frame=''>0 0 0 -3.14159 -1.57079 -1.57079</pose>
          <geometry>
            <mesh>
              <scale>0.001 0.001 0.001</scale>
              <uri>/home/zach/ros_ws/src/tr2_essentials/tr2_description/meshes/stl/link_g1_b.stl</uri>
            </mesh>
          </geometry>
          <material>
            <script>
              <name>Gazebo/DarkGrey</name>
              <uri>file://media/materials/scripts/gazebo.material</uri>
            </script>
          </material>
        </visual>
        <gravity>1</gravity>
        <velocity_decay/>
        <self_collide>0</self_collide>
        <enable_wind>0</enable_wind>
        <kinematic>0</kinematic>
      </link>
      <joint name='g0_b' type='prismatic'>
        <child>link_g1_b</child>
        <parent>link_g0</parent>
        <axis>
          <xyz>4.3e-05 0.866025 -0.500001</xyz>
          <limit>
            <lower>-0.041</lower>
            <upper>0</upper>
            <effort>100</effort>
            <velocity>0.01</velocity>
          </limit>
          <dynamics>
            <damping>0.1</damping>
            <friction>0.1</friction>
            <spring_reference>0</spring_reference>
            <spring_stiffness>0</spring_stiffness>
          </dynamics>
          <use_parent_model_frame>1</use_parent_model_frame>
        </axis>
      </joint>
      <link name='link_b0'>
        <pose frame=''>-0.3019 0.1502 0.0508 0 -0 1.5708</pose>
        <inertial>
          <pose frame=''>0 0 0 0 -0 0</pose>
          <mass>12</mass>
          <inertia>
            <ixx>0.1</ixx>
            <ixy>0</ixy>
            <ixz>0</ixz>
            <iyy>0.1</iyy>
            <iyz>0</iyz>
            <izz>0.1</izz>
          </inertia>
        </inertial>
        <collision name='link_b0_collision'>
          <pose frame=''>0 0 0 0 -0 1.5708</pose>
          <geometry>
            <mesh>
              <scale>0.001 0.001 0.001</scale>
              <uri>/home/zach/ros_ws/src/tr2_essentials/tr2_description/meshes/stl/link_b1.stl</uri>
            </mesh>
          </geometry>
          <surface>
            <contact>
              <ode>
                <kp>1e+15</kp>
                <kd>1e+13</kd>
              </ode>
            </contact>
            <friction>
              <ode>
                <mu>100000</mu>
                <mu2>100000</mu2>
                <slip1>0</slip1>
                <slip2>0</slip2>
              </ode>
              <torsional>
                <ode/>
              </torsional>
            </friction>
            <bounce/>
          </surface>
          <max_contacts>10</max_contacts>
        </collision>
        <visual name='link_b0_visual'>
          <pose frame=''>0 0 0 0 -0 1.5708</pose>
          <geometry>
            <mesh>
              <scale>0.001 0.001 0.001</scale>
              <uri>/home/zach/ros_ws/src/tr2_essentials/tr2_description/meshes/stl/link_b1.stl</uri>
            </mesh>
          </geometry>
          <material>
            <script>
              <name>Gazebo/DarkGrey</name>
              <uri>file://media/materials/scripts/gazebo.material</uri>
            </script>
          </material>
        </visual>
        <gravity>1</gravity>
        <velocity_decay/>
        <self_collide>0</self_collide>
        <enable_wind>0</enable_wind>
        <kinematic>0</kinematic>
      </link>
      <joint name='b0' type='revolute'>
        <child>link_b0</child>
        <parent>base_link</parent>
        <axis>
          <xyz>-1 0 0</xyz>
          <limit>
            <lower>-1e+16</lower>
            <upper>1e+16</upper>
          </limit>
          <dynamics>
            <damping>1</damping>
            <friction>2</friction>
            <spring_reference>0</spring_reference>
            <spring_stiffness>0</spring_stiffness>
          </dynamics>
          <use_parent_model_frame>1</use_parent_model_frame>
        </axis>
      </joint>
      <link name='link_b1'>
        <pose frame=''>0.3019 0.1502 0.0508 0 -0 1.5708</pose>
        <inertial>
          <pose frame=''>0 0 0 0 -0 0</pose>
          <mass>12</mass>
          <inertia>
            <ixx>0.1</ixx>
            <ixy>0</ixy>
            <ixz>0</ixz>
            <iyy>0.1</iyy>
            <iyz>0</iyz>
            <izz>0.1</izz>
          </inertia>
        </inertial>
        <collision name='link_b1_collision'>
          <pose frame=''>0 0 0 0 -0 1.5708</pose>
          <geometry>
            <mesh>
              <scale>0.001 0.001 0.001</scale>
              <uri>/home/zach/ros_ws/src/tr2_essentials/tr2_description/meshes/stl/link_b1.stl</uri>
            </mesh>
          </geometry>
          <surface>
            <contact>
              <ode>
                <kp>1e+15</kp>
                <kd>1e+13</kd>
              </ode>
            </contact>
            <friction>
              <ode>
                <mu>100000</mu>
                <mu2>100000</mu2>
                <slip1>0</slip1>
                <slip2>0</slip2>
              </ode>
              <torsional>
                <ode/>
              </torsional>
            </friction>
            <bounce/>
          </surface>
          <max_contacts>10</max_contacts>
        </collision>
        <visual name='link_b1_visual'>
          <pose frame=''>0 0 0 0 -0 1.5708</pose>
          <geometry>
            <mesh>
              <scale>0.001 0.001 0.001</scale>
              <uri>/home/zach/ros_ws/src/tr2_essentials/tr2_description/meshes/stl/link_b1.stl</uri>
            </mesh>
          </geometry>
          <material>
            <script>
              <name>Gazebo/DarkGrey</name>
              <uri>file://media/materials/scripts/gazebo.material</uri>
            </script>
          </material>
        </visual>
        <gravity>1</gravity>
        <velocity_decay/>
        <self_collide>0</self_collide>
        <enable_wind>0</enable_wind>
        <kinematic>0</kinematic>
      </link>
      <joint name='b1' type='revolute'>
        <child>link_b1</child>
        <parent>base_link</parent>
        <axis>
          <xyz>-1 0 0</xyz>
          <limit>
            <lower>-1e+16</lower>
            <upper>1e+16</upper>
          </limit>
          <dynamics>
            <damping>1</damping>
            <friction>2</friction>
            <spring_reference>0</spring_reference>
            <spring_stiffness>0</spring_stiffness>
          </dynamics>
          <use_parent_model_frame>1</use_parent_model_frame>
        </axis>
      </joint>
      <link name='link_b2'>
        <pose frame=''>0 -0.196 0 3.14159 9.3e-05 1.57079</pose>
        <inertial>
          <pose frame=''>0 0 0 0 -0 0</pose>
          <mass>1</mass>
          <inertia>
            <ixx>0.1</ixx>
            <ixy>0</ixy>
            <ixz>0</ixz>
            <iyy>0.1</iyy>
            <iyz>0</iyz>
            <izz>0.1</izz>
          </inertia>
        </inertial>
        <collision name='link_b2_collision'>
          <pose frame=''>0 0 0 0 -0 1.5708</pose>
          <geometry>
            <mesh>
              <scale>0.001 0.001 0.001</scale>
              <uri>/home/zach/ros_ws/src/tr2_essentials/tr2_description/meshes/stl/link_b2.stl</uri>
            </mesh>
          </geometry>
          <surface>
            <contact>
              <ode/>
            </contact>
            <friction>
              <ode/>
              <torsional>
                <ode/>
              </torsional>
            </friction>
            <bounce/>
          </surface>
          <max_contacts>10</max_contacts>
        </collision>
        <visual name='link_b2_visual'>
          <pose frame=''>0 0 0 0 -0 1.5708</pose>
          <geometry>
            <mesh>
              <scale>0.001 0.001 0.001</scale>
              <uri>/home/zach/ros_ws/src/tr2_essentials/tr2_description/meshes/stl/link_b2.stl</uri>
            </mesh>
          </geometry>
          <material>
            <script>
              <name>Gazebo/DarkGrey</name>
              <uri>file://media/materials/scripts/gazebo.material</uri>
            </script>
          </material>
        </visual>
        <gravity>1</gravity>
        <velocity_decay/>
        <self_collide>0</self_collide>
        <enable_wind>0</enable_wind>
        <kinematic>0</kinematic>
      </link>
      <joint name='b2' type='revolute'>
        <child>link_b2</child>
        <parent>base_link</parent>
        <axis>
          <xyz>-0 -9.3e-05 -1</xyz>
          <limit>
            <lower>-1e+16</lower>
            <upper>1e+16</upper>
          </limit>
          <dynamics>
            <damping>0.1</damping>
            <friction>0.1</friction>
            <spring_reference>0</spring_reference>
            <spring_stiffness>0</spring_stiffness>
          </dynamics>
          <use_parent_model_frame>1</use_parent_model_frame>
        </axis>
      </joint>
      <link name='link_b3'>
        <pose frame=''>-0 -0.209804 -0.038999 -1.57079 9.3e-05 1.57079</pose>
        <inertial>
          <pose frame=''>0 0 0 0 -0 0</pose>
          <mass>1</mass>
          <inertia>
            <ixx>0.1</ixx>
            <ixy>0</ixy>
            <ixz>0</ixz>
            <iyy>0.1</iyy>
            <iyz>0</iyz>
            <izz>0.1</izz>
          </inertia>
        </inertial>
        <collision name='link_b3_collision'>
          <pose frame=''>0 0 0 0 -0 1.5708</pose>
          <geometry>
            <mesh>
              <scale>0.001 0.001 0.001</scale>
              <uri>/home/zach/ros_ws/src/tr2_essentials/tr2_description/meshes/stl/link_b3.stl</uri>
            </mesh>
          </geometry>
          <surface>
            <contact>
              <ode/>
            </contact>
            <friction>
              <ode/>
              <torsional>
                <ode/>
              </torsional>
            </friction>
            <bounce/>
          </surface>
          <max_contacts>10</max_contacts>
        </collision>
        <visual name='link_b3_visual'>
          <pose frame=''>0 0 0 0 -0 1.5708</pose>
          <geometry>
            <mesh>
              <scale>0.001 0.001 0.001</scale>
              <uri>/home/zach/ros_ws/src/tr2_essentials/tr2_description/meshes/stl/link_b3.stl</uri>
            </mesh>
          </geometry>
          <material>
            <script>
              <name>Gazebo/DarkGrey</name>
              <uri>file://media/materials/scripts/gazebo.material</uri>
            </script>
          </material>
        </visual>
        <gravity>1</gravity>
        <velocity_decay/>
        <self_collide>0</self_collide>
        <enable_wind>0</enable_wind>
        <kinematic>0</kinematic>
      </link>
      <joint name='b3' type='revolute'>
        <child>link_b3</child>
        <parent>link_b2</parent>
        <axis>
          <xyz>-1 4e-06 4e-06</xyz>
          <limit>
            <lower>-1e+16</lower>
            <upper>1e+16</upper>
          </limit>
          <dynamics>
            <damping>0.1</damping>
            <friction>0.1</friction>
            <spring_reference>0</spring_reference>
            <spring_stiffness>0</spring_stiffness>
          </dynamics>
          <use_parent_model_frame>1</use_parent_model_frame>
        </axis>
      </joint>
      <link name='neck_link'>
        <pose frame=''>0 -0.1227 0.9071 0 -0 0</pose>
        <inertial>
          <pose frame=''>0 0 0 0 -0 0</pose>
          <mass>0.005</mass>
          <inertia>
            <ixx>0.001</ixx>
            <ixy>0</ixy>
            <ixz>0</ixz>
            <iyy>0.001</iyy>
            <iyz>0</iyz>
            <izz>0.001</izz>
          </inertia>
        </inertial>
        <collision name='neck_link_collision'>
          <pose frame=''>0 0 0 -9.3e-05 9.3e-05 3.14159</pose>
          <geometry>
            <mesh>
              <scale>0.001 0.001 0.001</scale>
              <uri>/home/zach/ros_ws/src/tr2_essentials/tr2_description/meshes/stl/link_h0.stl</uri>
            </mesh>
          </geometry>
          <surface>
            <contact>
              <ode/>
            </contact>
            <friction>
              <ode/>
              <torsional>
                <ode/>
              </torsional>
            </friction>
            <bounce/>
          </surface>
          <max_contacts>10</max_contacts>
        </collision>
        <visual name='neck_link_visual'>
          <pose frame=''>0 0 0 -9.3e-05 9.3e-05 3.14159</pose>
          <geometry>
            <mesh>
              <scale>0.001 0.001 0.001</scale>
              <uri>/home/zach/ros_ws/src/tr2_essentials/tr2_description/meshes/stl/link_h0.stl</uri>
            </mesh>
          </geometry>
          <material>
            <script>
              <name>Gazebo/DarkGrey</name>
              <uri>file://media/materials/scripts/gazebo.material</uri>
            </script>
          </material>
        </visual>
        <gravity>1</gravity>
        <velocity_decay/>
        <self_collide>0</self_collide>
        <enable_wind>0</enable_wind>
        <kinematic>0</kinematic>
      </link>
      <joint name='h0' type='revolute'>
        <child>neck_link</child>
        <parent>base_link</parent>
        <axis>
          <xyz>0 0 1</xyz>
          <limit>
            <lower>-15</lower>
            <upper>15</upper>
            <effort>100</effort>
            <velocity>0.2</velocity>
          </limit>
          <dynamics>
            <damping>0.1</damping>
            <friction>0.1</friction>
            <spring_reference>0</spring_reference>
            <spring_stiffness>0</spring_stiffness>
          </dynamics>
          <use_parent_model_frame>1</use_parent_model_frame>
        </axis>
      </joint>
      <link name='head_link'>
        <pose frame=''>-0.0688 0.0518 1.0685 -0.349 0 0</pose>
        <inertial>
          <pose frame=''>5e-05 0.000299 0 0 -0 0</pose>
          <mass>0.00501</mass>
          <inertia>
            <ixx>0.00110022</ixx>
            <ixy>-3.74251e-08</ixy>
            <ixz>0</ixz>
            <iyy>0.00110001</iyy>
            <iyz>0</iyz>
            <izz>0.00110023</izz>
          </inertia>
        </inertial>
        <collision name='head_link_collision'>
          <pose frame=''>0 0 0 3.14159 9.3e-05 3.14159</pose>
          <geometry>
            <mesh>
              <scale>0.001 0.001 0.001</scale>
              <uri>/home/zach/ros_ws/src/tr2_essentials/tr2_description/meshes/stl/link_h1.stl</uri>
            </mesh>
          </geometry>
          <surface>
            <contact>
              <ode/>
            </contact>
            <friction>
              <ode/>
              <torsional>
                <ode/>
              </torsional>
            </friction>
            <bounce/>
          </surface>
          <max_contacts>10</max_contacts>
        </collision>
        <collision name='head_link_fixed_joint_lump__camera_link_collision_1'>
          <pose frame=''>0.025 0.15 0 0 -0 0</pose>
          <geometry>
            <box>
              <size>0.01 0.01 0.01</size>
            </box>
          </geometry>
          <max_contacts>10</max_contacts>
          <surface>
            <contact>
              <ode/>
            </contact>
            <bounce/>
            <friction>
              <torsional>
                <ode/>
              </torsional>
              <ode/>
            </friction>
          </surface>
        </collision>
        <visual name='head_link_visual'>
          <pose frame=''>0 0 0 3.14159 9.3e-05 3.14159</pose>
          <geometry>
            <mesh>
              <scale>0.001 0.001 0.001</scale>
              <uri>/home/zach/ros_ws/src/tr2_essentials/tr2_description/meshes/stl/link_h1.stl</uri>
            </mesh>
          </geometry>
          <material>
            <script>
              <name>Gazebo/DarkGrey</name>
              <uri>file://media/materials/scripts/gazebo.material</uri>
            </script>
          </material>
        </visual>
        <velocity_decay/>
        <gravity>1</gravity>
        <velocity_decay/>
        <sensor name='orbbec_astra' type='depth'>
          <always_on>1</always_on>
          <visualize>1</visualize>
          <camera name='__default__'>
            <pose frame=''>0 0 0 -9.3e-05 -1.57079 1.57079</pose>
            <horizontal_fov>1</horizontal_fov>
            <image>
              <width>640</width>
              <height>480</height>
              <format>R8G8B8</format>
            </image>
            <depth_camera>
              <output>depths</output>
            </depth_camera>
            <clip>
              <near>0.6</near>
              <far>8</far>
            </clip>
          </camera>
          <plugin name='camera_controller' filename='libgazebo_ros_openni_kinect.so'>
            <alwaysOn>1</alwaysOn>
            <updateRate>10.0</updateRate>
            <cameraName>camera</cameraName>
            <frameName>camera_link_optical</frameName>
            <imageTopicName>rgb/image_raw</imageTopicName>
            <depthImageTopicName>depth/image_raw</depthImageTopicName>
            <pointCloudTopicName>depth/points</pointCloudTopicName>
            <cameraInfoTopicName>rgb/camera_info</cameraInfoTopicName>
            <depthImageCameraInfoTopicName>depth/camera_info</depthImageCameraInfoTopicName>
            <pointCloudCutoff>0.4</pointCloudCutoff>
            <hackBaseline>0.07</hackBaseline>
            <distortionK1>0.0</distortionK1>
            <distortionK2>0.0</distortionK2>
            <distortionK3>0.0</distortionK3>
            <distortionT1>0.0</distortionT1>
            <distortionT2>0.0</distortionT2>
            <CxPrime>0.0</CxPrime>
            <Cx>0.0</Cx>
            <Cy>0.0</Cy>
            <focalLength>0.0</focalLength>
            <robotNamespace>/</robotNamespace>
          </plugin>
          <pose frame=''>0.025 0.15 0 -1.5708 0 0</pose>
        </sensor>
        <self_collide>0</self_collide>
        <enable_wind>0</enable_wind>
        <kinematic>0</kinematic>
      </link>
      <joint name='h1' type='revolute'>
        <child>head_link</child>
        <parent>neck_link</parent>
        <axis>
          <xyz>1 0 0</xyz>
          <limit>
            <lower>-15</lower>
            <upper>15</upper>
            <effort>100</effort>
            <velocity>0.2</velocity>
          </limit>
          <dynamics>
            <damping>0.1</damping>
            <friction>0.1</friction>
            <spring_reference>0</spring_reference>
            <spring_stiffness>0</spring_stiffness>
          </dynamics>
          <use_parent_model_frame>1</use_parent_model_frame>
        </axis>
      </joint>
      <plugin name='g0_b_mimic_joint_plugin' filename='libroboticsgroup_gazebo_mimic_joint_plugin.so'>
        <joint>g0</joint>
        <mimicJoint>g0_b</mimicJoint>
        <multiplier>-1</multiplier>
        <robotNamespace>/</robotNamespace>
      </plugin>
      <static>0</static>
      <plugin name='gazebo_ros_control' filename='libgazebo_ros_control.so'>
        <robotNamespace>/</robotNamespace>
        <robotSimType>gazebo_ros_control/DefaultRobotHWSim</robotSimType>
        <legacyModeNS>1</legacyModeNS>
      </plugin>
      <pose frame=''>0 0 0.045 0 -0 0</pose>
    </model>
    <model name='unit_box'>
      <pose frame=''>-0.534803 2.52837 0.5 0 -0 0</pose>
      <link name='link'>
        <inertial>
          <mass>1</mass>
          <inertia>
            <ixx>0.166667</ixx>
            <ixy>0</ixy>
            <ixz>0</ixz>
            <iyy>0.166667</iyy>
            <iyz>0</iyz>
            <izz>0.166667</izz>
          </inertia>
        </inertial>
        <collision name='collision'>
          <geometry>
            <box>
              <size>1 1 1</size>
            </box>
          </geometry>
          <max_contacts>10</max_contacts>
          <surface>
            <contact>
              <ode/>
            </contact>
            <bounce/>
            <friction>
              <torsional>
                <ode/>
              </torsional>
              <ode/>
            </friction>
          </surface>
        </collision>
        <visual name='visual'>
          <geometry>
            <box>
              <size>1 1 1</size>
            </box>
          </geometry>
          <material>
            <script>
              <name>Gazebo/Grey</name>
              <uri>file://media/materials/scripts/gazebo.material</uri>
            </script>
          </material>
        </visual>
        <self_collide>0</self_collide>
        <enable_wind>0</enable_wind>
        <kinematic>0</kinematic>
      </link>
    </model>
    <model name='unit_box_0'>
      <pose frame=''>1.4748 5.52292 0.5 0 -0 0</pose>
      <link name='link'>
        <inertial>
          <mass>1</mass>
          <inertia>
            <ixx>0.166667</ixx>
            <ixy>0</ixy>
            <ixz>0</ixz>
            <iyy>0.166667</iyy>
            <iyz>0</iyz>
            <izz>0.166667</izz>
          </inertia>
        </inertial>
        <collision name='collision'>
          <geometry>
            <box>
              <size>1 1 1</size>
            </box>
          </geometry>
          <max_contacts>10</max_contacts>
          <surface>
            <contact>
              <ode/>
            </contact>
            <bounce/>
            <friction>
              <torsional>
                <ode/>
              </torsional>
              <ode/>
            </friction>
          </surface>
        </collision>
        <visual name='visual'>
          <geometry>
            <box>
              <size>1 1 1</size>
            </box>
          </geometry>
          <material>
            <script>
              <name>Gazebo/Grey</name>
              <uri>file://media/materials/scripts/gazebo.material</uri>
            </script>
          </material>
        </visual>
        <self_collide>0</self_collide>
        <enable_wind>0</enable_wind>
        <kinematic>0</kinematic>
      </link>
    </model>
    <state world_name='default'>
      <sim_time>230 482000000</sim_time>
      <real_time>299 259616878</real_time>
      <wall_time>1570419858 727724986</wall_time>
      <iterations>167579</iterations>
      <model name='ground_plane'>
        <pose frame=''>0 0 0 0 -0 0</pose>
        <scale>1 1 1</scale>
        <link name='link'>
          <pose frame=''>0 0 0 0 -0 0</pose>
          <velocity>0 0 0 0 -0 0</velocity>
          <acceleration>0 0 0 0 -0 0</acceleration>
          <wrench>0 0 0 0 -0 0</wrench>
        </link>
      </model>
      <model name='tr2'>
        <pose frame=''>-0.14294 0.231297 0.053498 -0.029372 0.000411 -1.43323</pose>
        <scale>1 1 1</scale>
        <link name='base_link'>
          <pose frame=''>-0.14294 0.231297 0.053498 -0.029372 0.000411 -1.43323</pose>
          <velocity>-0.010224 0.003843 0.005383 -0.002973 0.039152 -0.036535</velocity>
          <acceleration>-26.6487 0.917322 56.7888 -1.7244 0.676068 -3.12896</acceleration>
          <wrench>-26.6487 0.917322 56.7888 0 -0 0</wrench>
        </link>
        <link name='head_link'>
          <pose frame=''>-0.070449 0.311306 1.12006 -0.343515 0.000568 -1.4278</pose>
          <velocity>0.035003 0.004233 0.002177 0.00197 0.003759 -0.036721</velocity>
          <acceleration>400.53 56.2608 26.2597 2.25745 0.843675 -2.90342</acceleration>
          <wrench>2.00665 0.281866 0.131561 0 -0 0</wrench>
        </link>
        <link name='link_a0'>
          <pose frame=''>0.01804 0.159093 0.778579 -3.11224 -0.001165 1.7372</pose>
          <velocity>0.015268 8e-05 -0.000576 -0.003444 0.03974 -0.035326</velocity>
          <acceleration>262.17 30.4791 -3.67908 -2.82339 -1.15558 0.183775</acceleration>
          <wrench>1.31085 0.152396 -0.018395 0 -0 0</wrench>
        </link>
        <link name='link_a1'>
          <pose frame=''>0.063968 0.384309 0.866142 1.85018 1.54026 -2.69556</pose>
          <velocity>0.026408 -0.001368 -0.002842 -0.003824 0.040124 -0.03519</velocity>
          <acceleration>233.227 46.6541 -30.3081 -0.891519 -0.098085 -2.70379</acceleration>
          <wrench>1.16613 0.233271 -0.15154 0 -0 0</wrench>
        </link>
        <link name='link_a2'>
          <pose frame=''>0.167506 0.400287 0.6961 -1.87915 -1.54028 0.443103</pose>
          <velocity>0.020127 -0.005629 -0.006868 -0.004383 0.040117 -0.048473</velocity>
          <acceleration>162.787 59.1352 -71.8859 0.004662 0.616937 0.316495</acceleration>
          <wrench>0.813936 0.295676 -0.359429 0 -0 0</wrench>
        </link>
        <link name='link_a3'>
          <pose frame=''>0.084008 0.387534 0.544097 -0.029072 0.003578 -1.43628</pose>
          <velocity>0.013373 -0.002248 -0.003365 -0.004513 0.04009 -0.04861</velocity>
          <acceleration>104.461 43.7461 -38.3415 -1.47016 -1.47423 1.51621</acceleration>
          <wrench>0.522303 0.218731 -0.191707 0 -0 0</wrench>
        </link>
        <link name='link_b0'>
          <pose frame=''>-0.03414 0.551118 0.09999 3.14101 -0.806089 -3.00362</pose>
          <velocity>0.002679 0.000127 -2.7e-05 -0.001648 0.025841 -0.036136</velocity>
          <acceleration>1.72377 -1.05302 -0.746356 -0.025797 -0.90919 -1.48558</acceleration>
          <wrench>20.6853 -12.6362 -8.95627 0 -0 0</wrench>
        </link>
        <link name='link_b1'>
          <pose frame=''>0.048679 -0.046975 0.099743 3.14052 -1.16994 -3.00306</pose>
          <velocity>-0.023742 -0.003043 -0.001695 0.032951 -0.237986 -0.034392</velocity>
          <acceleration>2.41267 -1.08306 -4.4202 0.644228 0.779965 0.975118</acceleration>
          <wrench>28.9521 -12.9967 -53.0424 0 -0 0</wrench>
        </link>
        <link name='link_b2'>
          <pose frame=''>-0.336981 0.204434 0.059262 -3.12632 -0.025194 2.71999</pose>
          <velocity>-0.014467 0.010968 0.011906 -0.003438 0.039642 -0.047272</velocity>
          <acceleration>-17.3726 2.2244 136.445 0.850019 0.90521 0.277733</acceleration>
          <wrench>-17.3726 2.2244 136.445 0 -0 0</wrench>
        </link>
        <link name='link_b3'>
          <pose frame=''>-0.325492 0.198656 0.019933 1.55261 0.574618 -0.431101</pose>
          <velocity>-0.022409 0.010424 0.011156 -0.519617 -1.1113 -0.027646</velocity>
          <acceleration>-30.9027 1.92176 132.069 -0.631297 -1.00561 -1.18306</acceleration>
          <wrench>-30.9027 1.92176 132.069 0 -0 0</wrench>
        </link>
        <link name='link_g0'>
          <pose frame=''>-0.002271 0.207425 0.546689 -2.62403 -0.003486 1.70532</pose>
          <velocity>0.004655 0.001939 0.000928 0.00026 0.004314 -0.04877</velocity>
          <acceleration>102.174 45.2039 3.18717 0.695429 0.240138 -0.19595</acceleration>
          <wrench>0.510872 0.226019 0.015936 0 -0 0</wrench>
        </link>
        <link name='link_g1'>
          <pose frame=''>0.046766 0.077895 0.528442 -2.62403 -0.003486 1.70532</pose>
          <velocity>-0.0017 -0.00043 0.000641 0.00028 0.004317 -0.048768</velocity>
          <acceleration>33.6567 35.4964 38.9857 0.664526 0.235387 -0.102959</acceleration>
          <wrench>0.168283 0.177482 0.194928 0 -0 0</wrench>
        </link>
        <link name='link_g1_b'>
          <pose frame=''>0.00879 0.072679 0.550266 -2.62403 -0.003486 1.70532</pose>
          <velocity>-0.001771 0.001448 0.000715 0.000352 0.004329 -0.048746</velocity>
          <acceleration>35.1643 36.2045 38.0521 0.689555 0.251537 0.242426</acceleration>
          <wrench>0.175822 0.181023 0.190261 0 -0 0</wrench>
        </link>
        <link name='neck_link'>
          <pose frame=''>-0.237988 0.217763 0.963811 -0.029369 0.000566 -1.4278</pose>
          <velocity>0.024408 0.010272 0.008904 -0.00277 0.039258 -0.036529</velocity>
          <acceleration>342.14 43.2679 94.7114 0.191203 -1.36397 -1.15426</acceleration>
          <wrench>1.7107 0.216339 0.473557 0 -0 0</wrench>
        </link>
      </model>
      <model name='unit_box'>
        <pose frame=''>-0.534803 2.52838 0.499995 -1e-05 -0 -0</pose>
        <scale>1 1 1</scale>
        <link name='link'>
          <pose frame=''>-0.534803 2.52838 0.499995 -1e-05 -0 -0</pose>
          <velocity>0 0 0 0 -0 0</velocity>
          <acceleration>0.004709 0.011055 -9.78158 -0.022108 0.009414 1e-06</acceleration>
          <wrench>0.004709 0.011055 -9.78158 0 -0 0</wrench>
        </link>
      </model>
      <model name='unit_box_0'>
        <pose frame=''>1.45629 5.5247 0.499995 -1e-05 -0 -0.001247</pose>
        <scale>1 1 1</scale>
        <link name='link'>
          <pose frame=''>1.45629 5.5247 0.499995 -1e-05 -0 -0.001247</pose>
          <velocity>0 0 0 0 -0 0</velocity>
          <acceleration>-0.00471 0.011062 -9.78157 -0.022121 -0.009417 -1e-06</acceleration>
          <wrench>-0.00471 0.011062 -9.78157 0 -0 0</wrench>
        </link>
      </model>
      <model name='unit_box_1'>
        <pose frame=''>-1.55028 2.54667 0.499995 0 1e-05 0</pose>
        <scale>1 1 1</scale>
        <link name='link'>
          <pose frame=''>-1.55028 2.54667 0.499995 0 1e-05 0</pose>
          <velocity>0 0 0 0 -0 0</velocity>
          <acceleration>0.010615 -0.006191 -9.78231 0.012424 0.021225 1.8e-05</acceleration>
          <wrench>0.010615 -0.006191 -9.78231 0 -0 0</wrench>
        </link>
      </model>
      <model name='unit_box_10'>
        <pose frame=''>3.42744 -0.499799 0.499995 -1e-05 -0 -0</pose>
        <scale>1 1 1</scale>
        <link name='link'>
          <pose frame=''>3.42744 -0.499799 0.499995 -1e-05 -0 -0</pose>
          <velocity>0 0 0 0 -0 0</velocity>
          <acceleration>0.004709 0.011055 -9.78158 -0.022108 0.009414 1e-06</acceleration>
          <wrench>0.004709 0.011055 -9.78158 0 -0 0</wrench>
        </link>
      </model>
      <model name='unit_box_11'>
        <pose frame=''>3.48694 0.501613 0.499995 1e-05 -0 0.000216</pose>
        <scale>1 1 1</scale>
        <link name='link'>
          <pose frame=''>3.48694 0.501613 0.499995 1e-05 -0 0.000216</pose>
          <velocity>0 0 0 0 -0 0</velocity>
          <acceleration>0.004708 -0.011054 -9.78158 0.022105 0.009413 -1e-06</acceleration>
          <wrench>0.004708 -0.011054 -9.78158 0 -0 0</wrench>
        </link>
      </model>
      <model name='unit_box_12'>
        <pose frame=''>3.45027 1.50178 0.499995 -0 -1e-05 0.000517</pose>
        <scale>1 1 1</scale>
        <link name='link'>
          <pose frame=''>3.45027 1.50178 0.499995 -0 -1e-05 0.000517</pose>
          <velocity>0 0 0 0 -0 0</velocity>
          <acceleration>-0.010611 -0.006192 -9.78231 0.012423 -0.021218 -1.8e-05</acceleration>
          <wrench>-0.010611 -0.006192 -9.78231 0 -0 0</wrench>
        </link>
      </model>
      <model name='unit_box_13'>
        <pose frame=''>3.45724 2.50183 0.499995 0 -1e-05 0.000482</pose>
        <scale>1 1 1</scale>
        <link name='link'>
          <pose frame=''>3.45724 2.50183 0.499995 0 -1e-05 0.000482</pose>
          <velocity>0 0 0 0 -0 0</velocity>
          <acceleration>-0.010611 -0.006192 -9.78231 0.012423 -0.021219 -1.8e-05</acceleration>
          <wrench>-0.010611 -0.006192 -9.78231 0 -0 0</wrench>
        </link>
      </model>
      <model name='unit_box_14'>
        <pose frame=''>3.49896 3.51239 0.499995 0 -1e-05 -0.005308</pose>
        <scale>1 1 1</scale>
        <link name='link'>
          <pose frame=''>3.49896 3.51239 0.499995 0 -1e-05 -0.005308</pose>
          <velocity>0 0 0 0 -0 0</velocity>
          <acceleration>-0.010577 0.006193 -9.78232 -0.012416 -0.021152 1.3e-05</acceleration>
          <wrench>-0.010577 0.006193 -9.78232 0 -0 0</wrench>
        </link>
      </model>
      <model name='unit_box_15'>
        <pose frame=''>3.50355 4.51243 0.499961 0 0 -0.005303</pose>
        <scale>1 1 1</scale>
        <link name='link'>
          <pose frame=''>3.50355 4.51243 0.499961 0 0 -0.005303</pose>
          <velocity>0 0 0 0 -0 0</velocity>
          <acceleration>0 -0 -9.8 -0 -0 -0</acceleration>
          <wrench>0 -0 -9.8 0 -0 0</wrench>
        </link>
      </model>
      <model name='unit_box_16'>
        <pose frame=''>2.45636 5.55431 0.5 -0 -0 -0.001304</pose>
        <scale>1 1 1</scale>
        <link name='link'>
          <pose frame=''>2.45636 5.55431 0.5 -0 -0 -0.001304</pose>
          <velocity>0 0 0 0 -0 0</velocity>
          <acceleration>-0 0 0 -1e-06 -1e-06 0</acceleration>
          <wrench>-0 0 0 0 -0 0</wrench>
        </link>
      </model>
      <model name='unit_box_17'>
        <pose frame=''>3.45639 5.51442 0.499995 1e-05 0 -0.001474</pose>
        <scale>1 1 1</scale>
        <link name='link'>
          <pose frame=''>3.45639 5.51442 0.499995 1e-05 0 -0.001474</pose>
          <velocity>0 0 0 0 -0 0</velocity>
          <acceleration>-0.004705 -0.011254 -9.78123 0.022506 -0.009406 1e-06</acceleration>
          <wrench>-0.004705 -0.011254 -9.78123 0 -0 0</wrench>
        </link>
      </model>
      <model name='unit_box_2'>
        <pose frame=''>-2.55728 1.46454 0.499995 -1e-05 -0 -0</pose>
        <scale>1 1 1</scale>
        <link name='link'>
          <pose frame=''>-2.55728 1.46454 0.499995 -1e-05 -0 -0</pose>
          <velocity>0 0 0 0 -0 0</velocity>
          <acceleration>0.004709 0.011055 -9.78158 -0.022108 0.009414 1e-06</acceleration>
          <wrench>0.004709 0.011055 -9.78158 0 -0 0</wrench>
        </link>
      </model>
      <model name='unit_box_3'>
        <pose frame=''>-2.56485 0.419029 0.499995 0 1e-05 0</pose>
        <scale>1 1 1</scale>
        <link name='link'>
          <pose frame=''>-2.56485 0.419029 0.499995 0 1e-05 0</pose>
          <velocity>0 0 0 0 -0 0</velocity>
          <acceleration>0.010615 -0.006191 -9.78231 0.012424 0.021225 1.8e-05</acceleration>
          <wrench>0.010615 -0.006191 -9.78231 0 -0 0</wrench>
        </link>
      </model>
      <model name='unit_box_4'>
        <pose frame=''>-2.58749 -0.630073 0.499995 -1e-05 -0 -0</pose>
        <scale>1 1 1</scale>
        <link name='link'>
          <pose frame=''>-2.58749 -0.630073 0.499995 -1e-05 -0 -0</pose>
          <velocity>0 0 0 0 -0 0</velocity>
          <acceleration>0.004709 0.011055 -9.78158 -0.022108 0.009414 1e-06</acceleration>
          <wrench>0.004709 0.011055 -9.78158 0 -0 0</wrench>
        </link>
      </model>
      <model name='unit_box_5'>
        <pose frame=''>-1.53712 -1.51928 0.499995 0 1e-05 0.000386</pose>
        <scale>1 1 1</scale>
        <link name='link'>
          <pose frame=''>-1.53712 -1.51928 0.499995 0 1e-05 0.000386</pose>
          <velocity>0 0 0 0 -0 0</velocity>
          <acceleration>0.214372 -0.005302 -9.44272 0.010647 0.428735 3.4e-05</acceleration>
          <wrench>0.214372 -0.005302 -9.44272 0 -0 0</wrench>
        </link>
      </model>
      <model name='unit_box_6'>
        <pose frame=''>-0.537133 -1.51006 0.499995 0 -1e-05 0.000386</pose>
        <scale>1 1 1</scale>
        <link name='link'>
          <pose frame=''>-0.537133 -1.51006 0.499995 0 -1e-05 0.000386</pose>
          <velocity>0 0 0 0 -0 0</velocity>
          <acceleration>-0.139821 -0.005665 -9.56696 0.011356 -0.279634 -2.3e-05</acceleration>
          <wrench>-0.139821 -0.005665 -9.56696 0 -0 0</wrench>
        </link>
      </model>
      <model name='unit_box_7'>
        <pose frame=''>0.464658 -1.5069 0.499995 1e-05 -0 -0.000544</pose>
        <scale>1 1 1</scale>
        <link name='link'>
          <pose frame=''>0.464658 -1.5069 0.499995 1e-05 -0 -0.000544</pose>
          <velocity>0 0 0 0 -0 0</velocity>
          <acceleration>-0.004708 -0.011053 -9.78158 0.022102 -0.009412 1e-06</acceleration>
          <wrench>-0.004708 -0.011053 -9.78158 0 -0 0</wrench>
        </link>
      </model>
      <model name='unit_box_8'>
        <pose frame=''>1.46478 -1.5001 0.499995 0 -1e-05 -0.00076</pose>
        <scale>1 1 1</scale>
        <link name='link'>
          <pose frame=''>1.46478 -1.5001 0.499995 0 -1e-05 -0.00076</pose>
          <velocity>0 0 0 0 -0 0</velocity>
          <acceleration>-0.010609 0.006192 -9.78231 -0.012423 -0.021215 1.8e-05</acceleration>
          <wrench>-0.010609 0.006192 -9.78231 0 -0 0</wrench>
        </link>
      </model>
      <model name='unit_box_9'>
        <pose frame=''>2.46479 -1.52674 0.499995 0 -1e-05 -0.000718</pose>
        <scale>1 1 1</scale>
        <link name='link'>
          <pose frame=''>2.46479 -1.52674 0.499995 0 -1e-05 -0.000718</pose>
          <velocity>0 0 0 0 -0 0</velocity>
          <acceleration>-0.010619 -0.006191 -9.78231 0.012425 -0.021235 -1.9e-05</acceleration>
          <wrench>-0.010619 -0.006191 -9.78231 0 -0 0</wrench>
        </link>
      </model>
      <light name='sun'>
        <pose frame=''>0 0 10 0 -0 0</pose>
      </light>
    </state>
    <model name='unit_box_1'>
      <pose frame=''>-1.55028 2.54667 0.5 0 -0 0</pose>
      <link name='link'>
        <inertial>
          <mass>1</mass>
          <inertia>
            <ixx>0.166667</ixx>
            <ixy>0</ixy>
            <ixz>0</ixz>
            <iyy>0.166667</iyy>
            <iyz>0</iyz>
            <izz>0.166667</izz>
          </inertia>
        </inertial>
        <collision name='collision'>
          <geometry>
            <box>
              <size>1 1 1</size>
            </box>
          </geometry>
          <max_contacts>10</max_contacts>
          <surface>
            <contact>
              <ode/>
            </contact>
            <bounce/>
            <friction>
              <torsional>
                <ode/>
              </torsional>
              <ode/>
            </friction>
          </surface>
        </collision>
        <visual name='visual'>
          <geometry>
            <box>
              <size>1 1 1</size>
            </box>
          </geometry>
          <material>
            <script>
              <name>Gazebo/Grey</name>
              <uri>file://media/materials/scripts/gazebo.material</uri>
            </script>
          </material>
        </visual>
        <self_collide>0</self_collide>
        <enable_wind>0</enable_wind>
        <kinematic>0</kinematic>
      </link>
    </model>
    <model name='unit_box_2'>
      <pose frame=''>-2.55728 1.46454 0.5 0 -0 0</pose>
      <link name='link'>
        <inertial>
          <mass>1</mass>
          <inertia>
            <ixx>0.166667</ixx>
            <ixy>0</ixy>
            <ixz>0</ixz>
            <iyy>0.166667</iyy>
            <iyz>0</iyz>
            <izz>0.166667</izz>
          </inertia>
        </inertial>
        <collision name='collision'>
          <geometry>
            <box>
              <size>1 1 1</size>
            </box>
          </geometry>
          <max_contacts>10</max_contacts>
          <surface>
            <contact>
              <ode/>
            </contact>
            <bounce/>
            <friction>
              <torsional>
                <ode/>
              </torsional>
              <ode/>
            </friction>
          </surface>
        </collision>
        <visual name='visual'>
          <geometry>
            <box>
              <size>1 1 1</size>
            </box>
          </geometry>
          <material>
            <script>
              <name>Gazebo/Grey</name>
              <uri>file://media/materials/scripts/gazebo.material</uri>
            </script>
          </material>
        </visual>
        <self_collide>0</self_collide>
        <enable_wind>0</enable_wind>
        <kinematic>0</kinematic>
      </link>
    </model>
    <model name='unit_box_3'>
      <pose frame=''>-2.56485 0.419029 0.5 0 -0 0</pose>
      <link name='link'>
        <inertial>
          <mass>1</mass>
          <inertia>
            <ixx>0.166667</ixx>
            <ixy>0</ixy>
            <ixz>0</ixz>
            <iyy>0.166667</iyy>
            <iyz>0</iyz>
            <izz>0.166667</izz>
          </inertia>
        </inertial>
        <collision name='collision'>
          <geometry>
            <box>
              <size>1 1 1</size>
            </box>
          </geometry>
          <max_contacts>10</max_contacts>
          <surface>
            <contact>
              <ode/>
            </contact>
            <bounce/>
            <friction>
              <torsional>
                <ode/>
              </torsional>
              <ode/>
            </friction>
          </surface>
        </collision>
        <visual name='visual'>
          <geometry>
            <box>
              <size>1 1 1</size>
            </box>
          </geometry>
          <material>
            <script>
              <name>Gazebo/Grey</name>
              <uri>file://media/materials/scripts/gazebo.material</uri>
            </script>
          </material>
        </visual>
        <self_collide>0</self_collide>
        <enable_wind>0</enable_wind>
        <kinematic>0</kinematic>
      </link>
    </model>
    <model name='unit_box_4'>
      <pose frame=''>-2.58749 -0.630078 0.5 0 -0 0</pose>
      <link name='link'>
        <inertial>
          <mass>1</mass>
          <inertia>
            <ixx>0.166667</ixx>
            <ixy>0</ixy>
            <ixz>0</ixz>
            <iyy>0.166667</iyy>
            <iyz>0</iyz>
            <izz>0.166667</izz>
          </inertia>
        </inertial>
        <collision name='collision'>
          <geometry>
            <box>
              <size>1 1 1</size>
            </box>
          </geometry>
          <max_contacts>10</max_contacts>
          <surface>
            <contact>
              <ode/>
            </contact>
            <bounce/>
            <friction>
              <torsional>
                <ode/>
              </torsional>
              <ode/>
            </friction>
          </surface>
        </collision>
        <visual name='visual'>
          <geometry>
            <box>
              <size>1 1 1</size>
            </box>
          </geometry>
          <material>
            <script>
              <name>Gazebo/Grey</name>
              <uri>file://media/materials/scripts/gazebo.material</uri>
            </script>
          </material>
        </visual>
        <self_collide>0</self_collide>
        <enable_wind>0</enable_wind>
        <kinematic>0</kinematic>
      </link>
    </model>
    <model name='unit_box_5'>
      <pose frame=''>-1.50139 -1.5191 0.5 0 -0 0</pose>
      <link name='link'>
        <inertial>
          <mass>1</mass>
          <inertia>
            <ixx>0.166667</ixx>
            <ixy>0</ixy>
            <ixz>0</ixz>
            <iyy>0.166667</iyy>
            <iyz>0</iyz>
            <izz>0.166667</izz>
          </inertia>
        </inertial>
        <collision name='collision'>
          <geometry>
            <box>
              <size>1 1 1</size>
            </box>
          </geometry>
          <max_contacts>10</max_contacts>
          <surface>
            <contact>
              <ode/>
            </contact>
            <bounce/>
            <friction>
              <torsional>
                <ode/>
              </torsional>
              <ode/>
            </friction>
          </surface>
        </collision>
        <visual name='visual'>
          <geometry>
            <box>
              <size>1 1 1</size>
            </box>
          </geometry>
          <material>
            <script>
              <name>Gazebo/Grey</name>
              <uri>file://media/materials/scripts/gazebo.material</uri>
            </script>
          </material>
        </visual>
        <self_collide>0</self_collide>
        <enable_wind>0</enable_wind>
        <kinematic>0</kinematic>
      </link>
    </model>
    <model name='unit_box_6'>
      <pose frame=''>-0.572879 -1.51024 0.5 0 -0 0</pose>
      <link name='link'>
        <inertial>
          <mass>1</mass>
          <inertia>
            <ixx>0.166667</ixx>
            <ixy>0</ixy>
            <ixz>0</ixz>
            <iyy>0.166667</iyy>
            <iyz>0</iyz>
            <izz>0.166667</izz>
          </inertia>
        </inertial>
        <collision name='collision'>
          <geometry>
            <box>
              <size>1 1 1</size>
            </box>
          </geometry>
          <max_contacts>10</max_contacts>
          <surface>
            <contact>
              <ode/>
            </contact>
            <bounce/>
            <friction>
              <torsional>
                <ode/>
              </torsional>
              <ode/>
            </friction>
          </surface>
        </collision>
        <visual name='visual'>
          <geometry>
            <box>
              <size>1 1 1</size>
            </box>
          </geometry>
          <material>
            <script>
              <name>Gazebo/Grey</name>
              <uri>file://media/materials/scripts/gazebo.material</uri>
            </script>
          </material>
        </visual>
        <self_collide>0</self_collide>
        <enable_wind>0</enable_wind>
        <kinematic>0</kinematic>
      </link>
    </model>
    <model name='unit_box_7'>
      <pose frame=''>0.479157 -1.50705 0.5 0 -0 0</pose>
      <link name='link'>
        <inertial>
          <mass>1</mass>
          <inertia>
            <ixx>0.166667</ixx>
            <ixy>0</ixy>
            <ixz>0</ixz>
            <iyy>0.166667</iyy>
            <iyz>0</iyz>
            <izz>0.166667</izz>
          </inertia>
        </inertial>
        <collision name='collision'>
          <geometry>
            <box>
              <size>1 1 1</size>
            </box>
          </geometry>
          <max_contacts>10</max_contacts>
          <surface>
            <contact>
              <ode/>
            </contact>
            <bounce/>
            <friction>
              <torsional>
                <ode/>
              </torsional>
              <ode/>
            </friction>
          </surface>
        </collision>
        <visual name='visual'>
          <geometry>
            <box>
              <size>1 1 1</size>
            </box>
          </geometry>
          <material>
            <script>
              <name>Gazebo/Grey</name>
              <uri>file://media/materials/scripts/gazebo.material</uri>
            </script>
          </material>
        </visual>
        <self_collide>0</self_collide>
        <enable_wind>0</enable_wind>
        <kinematic>0</kinematic>
      </link>
    </model>
    <model name='unit_box_8'>
      <pose frame=''>1.47943 -1.50111 0.5 0 -0 0</pose>
      <link name='link'>
        <inertial>
          <mass>1</mass>
          <inertia>
            <ixx>0.166667</ixx>
            <ixy>0</ixy>
            <ixz>0</ixz>
            <iyy>0.166667</iyy>
            <iyz>0</iyz>
            <izz>0.166667</izz>
          </inertia>
        </inertial>
        <collision name='collision'>
          <geometry>
            <box>
              <size>1 1 1</size>
            </box>
          </geometry>
          <max_contacts>10</max_contacts>
          <surface>
            <contact>
              <ode/>
            </contact>
            <bounce/>
            <friction>
              <torsional>
                <ode/>
              </torsional>
              <ode/>
            </friction>
          </surface>
        </collision>
        <visual name='visual'>
          <geometry>
            <box>
              <size>1 1 1</size>
            </box>
          </geometry>
          <material>
            <script>
              <name>Gazebo/Grey</name>
              <uri>file://media/materials/scripts/gazebo.material</uri>
            </script>
          </material>
        </visual>
        <self_collide>0</self_collide>
        <enable_wind>0</enable_wind>
        <kinematic>0</kinematic>
      </link>
    </model>
    <model name='unit_box_9'>
      <pose frame=''>2.43544 -1.52644 0.5 0 -0 0</pose>
      <link name='link'>
        <inertial>
          <mass>1</mass>
          <inertia>
            <ixx>0.166667</ixx>
            <ixy>0</ixy>
            <ixz>0</ixz>
            <iyy>0.166667</iyy>
            <iyz>0</iyz>
            <izz>0.166667</izz>
          </inertia>
        </inertial>
        <collision name='collision'>
          <geometry>
            <box>
              <size>1 1 1</size>
            </box>
          </geometry>
          <max_contacts>10</max_contacts>
          <surface>
            <contact>
              <ode/>
            </contact>
            <bounce/>
            <friction>
              <torsional>
                <ode/>
              </torsional>
              <ode/>
            </friction>
          </surface>
        </collision>
        <visual name='visual'>
          <geometry>
            <box>
              <size>1 1 1</size>
            </box>
          </geometry>
          <material>
            <script>
              <name>Gazebo/Grey</name>
              <uri>file://media/materials/scripts/gazebo.material</uri>
            </script>
          </material>
        </visual>
        <self_collide>0</self_collide>
        <enable_wind>0</enable_wind>
        <kinematic>0</kinematic>
      </link>
    </model>
    <model name='unit_box_10'>
      <pose frame=''>3.42744 -0.499804 0.5 0 -0 0</pose>
      <link name='link'>
        <inertial>
          <mass>1</mass>
          <inertia>
            <ixx>0.166667</ixx>
            <ixy>0</ixy>
            <ixz>0</ixz>
            <iyy>0.166667</iyy>
            <iyz>0</iyz>
            <izz>0.166667</izz>
          </inertia>
        </inertial>
        <collision name='collision'>
          <geometry>
            <box>
              <size>1 1 1</size>
            </box>
          </geometry>
          <max_contacts>10</max_contacts>
          <surface>
            <contact>
              <ode/>
            </contact>
            <bounce/>
            <friction>
              <torsional>
                <ode/>
              </torsional>
              <ode/>
            </friction>
          </surface>
        </collision>
        <visual name='visual'>
          <geometry>
            <box>
              <size>1 1 1</size>
            </box>
          </geometry>
          <material>
            <script>
              <name>Gazebo/Grey</name>
              <uri>file://media/materials/scripts/gazebo.material</uri>
            </script>
          </material>
        </visual>
        <self_collide>0</self_collide>
        <enable_wind>0</enable_wind>
        <kinematic>0</kinematic>
      </link>
    </model>
    <model name='unit_box_11'>
      <pose frame=''>3.48691 0.515008 0.5 0 -0 0</pose>
      <link name='link'>
        <inertial>
          <mass>1</mass>
          <inertia>
            <ixx>0.166667</ixx>
            <ixy>0</ixy>
            <ixz>0</ixz>
            <iyy>0.166667</iyy>
            <iyz>0</iyz>
            <izz>0.166667</izz>
          </inertia>
        </inertial>
        <collision name='collision'>
          <geometry>
            <box>
              <size>1 1 1</size>
            </box>
          </geometry>
          <max_contacts>10</max_contacts>
          <surface>
            <contact>
              <ode/>
            </contact>
            <bounce/>
            <friction>
              <torsional>
                <ode/>
              </torsional>
              <ode/>
            </friction>
          </surface>
        </collision>
        <visual name='visual'>
          <geometry>
            <box>
              <size>1 1 1</size>
            </box>
          </geometry>
          <material>
            <script>
              <name>Gazebo/Grey</name>
              <uri>file://media/materials/scripts/gazebo.material</uri>
            </script>
          </material>
        </visual>
        <self_collide>0</self_collide>
        <enable_wind>0</enable_wind>
        <kinematic>0</kinematic>
      </link>
    </model>
    <model name='unit_box_12'>
      <pose frame=''>3.45022 1.49359 0.5 0 -0 0</pose>
      <link name='link'>
        <inertial>
          <mass>1</mass>
          <inertia>
            <ixx>0.166667</ixx>
            <ixy>0</ixy>
            <ixz>0</ixz>
            <iyy>0.166667</iyy>
            <iyz>0</iyz>
            <izz>0.166667</izz>
          </inertia>
        </inertial>
        <collision name='collision'>
          <geometry>
            <box>
              <size>1 1 1</size>
            </box>
          </geometry>
          <max_contacts>10</max_contacts>
          <surface>
            <contact>
              <ode/>
            </contact>
            <bounce/>
            <friction>
              <torsional>
                <ode/>
              </torsional>
              <ode/>
            </friction>
          </surface>
        </collision>
        <visual name='visual'>
          <geometry>
            <box>
              <size>1 1 1</size>
            </box>
          </geometry>
          <material>
            <script>
              <name>Gazebo/Grey</name>
              <uri>file://media/materials/scripts/gazebo.material</uri>
            </script>
          </material>
        </visual>
        <self_collide>0</self_collide>
        <enable_wind>0</enable_wind>
        <kinematic>0</kinematic>
      </link>
    </model>
    <model name='unit_box_13'>
      <pose frame=''>3.45721 2.4961 0.5 0 -0 0</pose>
      <link name='link'>
        <inertial>
          <mass>1</mass>
          <inertia>
            <ixx>0.166667</ixx>
            <ixy>0</ixy>
            <ixz>0</ixz>
            <iyy>0.166667</iyy>
            <iyz>0</iyz>
            <izz>0.166667</izz>
          </inertia>
        </inertial>
        <collision name='collision'>
          <geometry>
            <box>
              <size>1 1 1</size>
            </box>
          </geometry>
          <max_contacts>10</max_contacts>
          <surface>
            <contact>
              <ode/>
            </contact>
            <bounce/>
            <friction>
              <torsional>
                <ode/>
              </torsional>
              <ode/>
            </friction>
          </surface>
        </collision>
        <visual name='visual'>
          <geometry>
            <box>
              <size>1 1 1</size>
            </box>
          </geometry>
          <material>
            <script>
              <name>Gazebo/Grey</name>
              <uri>file://media/materials/scripts/gazebo.material</uri>
            </script>
          </material>
        </visual>
        <self_collide>0</self_collide>
        <enable_wind>0</enable_wind>
        <kinematic>0</kinematic>
      </link>
    </model>
    <model name='unit_box_14'>
      <pose frame=''>3.49702 3.52921 0.5 0 -0 0</pose>
      <link name='link'>
        <inertial>
          <mass>1</mass>
          <inertia>
            <ixx>0.166667</ixx>
            <ixy>0</ixy>
            <ixz>0</ixz>
            <iyy>0.166667</iyy>
            <iyz>0</iyz>
            <izz>0.166667</izz>
          </inertia>
        </inertial>
        <collision name='collision'>
          <geometry>
            <box>
              <size>1 1 1</size>
            </box>
          </geometry>
          <max_contacts>10</max_contacts>
          <surface>
            <contact>
              <ode/>
            </contact>
            <bounce/>
            <friction>
              <torsional>
                <ode/>
              </torsional>
              <ode/>
            </friction>
          </surface>
        </collision>
        <visual name='visual'>
          <geometry>
            <box>
              <size>1 1 1</size>
            </box>
          </geometry>
          <material>
            <script>
              <name>Gazebo/Grey</name>
              <uri>file://media/materials/scripts/gazebo.material</uri>
            </script>
          </material>
        </visual>
        <self_collide>0</self_collide>
        <enable_wind>0</enable_wind>
        <kinematic>0</kinematic>
      </link>
    </model>
    <model name='unit_box_15'>
      <pose frame=''>3.49131 4.50969 0.5 0 -0 0</pose>
      <link name='link'>
        <inertial>
          <mass>1</mass>
          <inertia>
            <ixx>0.166667</ixx>
            <ixy>0</ixy>
            <ixz>0</ixz>
            <iyy>0.166667</iyy>
            <iyz>0</iyz>
            <izz>0.166667</izz>
          </inertia>
        </inertial>
        <collision name='collision'>
          <geometry>
            <box>
              <size>1 1 1</size>
            </box>
          </geometry>
          <max_contacts>10</max_contacts>
          <surface>
            <contact>
              <ode/>
            </contact>
            <bounce/>
            <friction>
              <torsional>
                <ode/>
              </torsional>
              <ode/>
            </friction>
          </surface>
        </collision>
        <visual name='visual'>
          <geometry>
            <box>
              <size>1 1 1</size>
            </box>
          </geometry>
          <material>
            <script>
              <name>Gazebo/Grey</name>
              <uri>file://media/materials/scripts/gazebo.material</uri>
            </script>
          </material>
        </visual>
        <self_collide>0</self_collide>
        <enable_wind>0</enable_wind>
        <kinematic>0</kinematic>
      </link>
    </model>
    <model name='unit_box_16'>
      <pose frame=''>2.47386 5.54574 0.5 0 -0 0</pose>
      <link name='link'>
        <inertial>
          <mass>1</mass>
          <inertia>
            <ixx>0.166667</ixx>
            <ixy>0</ixy>
            <ixz>0</ixz>
            <iyy>0.166667</iyy>
            <iyz>0</iyz>
            <izz>0.166667</izz>
          </inertia>
        </inertial>
        <collision name='collision'>
          <geometry>
            <box>
              <size>1 1 1</size>
            </box>
          </geometry>
          <max_contacts>10</max_contacts>
          <surface>
            <contact>
              <ode/>
            </contact>
            <bounce/>
            <friction>
              <torsional>
                <ode/>
              </torsional>
              <ode/>
            </friction>
          </surface>
        </collision>
        <visual name='visual'>
          <geometry>
            <box>
              <size>1 1 1</size>
            </box>
          </geometry>
          <material>
            <script>
              <name>Gazebo/Grey</name>
              <uri>file://media/materials/scripts/gazebo.material</uri>
            </script>
          </material>
        </visual>
        <self_collide>0</self_collide>
        <enable_wind>0</enable_wind>
        <kinematic>0</kinematic>
      </link>
    </model>
    <model name='unit_box_17'>
      <pose frame=''>3.43151 5.51097 0.5 0 -0 0</pose>
      <link name='link'>
        <inertial>
          <mass>1</mass>
          <inertia>
            <ixx>0.166667</ixx>
            <ixy>0</ixy>
            <ixz>0</ixz>
            <iyy>0.166667</iyy>
            <iyz>0</iyz>
            <izz>0.166667</izz>
          </inertia>
        </inertial>
        <collision name='collision'>
          <geometry>
            <box>
              <size>1 1 1</size>
            </box>
          </geometry>
          <max_contacts>10</max_contacts>
          <surface>
            <contact>
              <ode/>
            </contact>
            <bounce/>
            <friction>
              <torsional>
                <ode/>
              </torsional>
              <ode/>
            </friction>
          </surface>
        </collision>
        <visual name='visual'>
          <geometry>
            <box>
              <size>1 1 1</size>
            </box>
          </geometry>
          <material>
            <script>
              <name>Gazebo/Grey</name>
              <uri>file://media/materials/scripts/gazebo.material</uri>
            </script>
          </material>
        </visual>
        <self_collide>0</self_collide>
        <enable_wind>0</enable_wind>
        <kinematic>0</kinematic>
      </link>
    </model>
  </world>
</sdf>
