<?xml version="1.0"?>
<robot xmlns:xacro="http://www.ros.org/wiki/xacro">

  <xacro:include filename="$(find tr2_description)/urdf/base/base.gazebo.xacro" />
	<xacro:include filename="$(find tr2_description)/urdf/base/base.transmission.xacro" />

	<!-- wheel macros -->
  <xacro:macro name="tr2_wheel" params="name *origin">
		<joint name="${name}" type="continuous">
			<parent link="base_link"/>
			<child link="${name}_link"/>
		  <axis xyz="0 1 0"/>
			<xacro:insert_block name="origin" />
    	<dynamics damping="0.1" friction="0.1"/>
		</joint>
		<link name="${name}_link">
			<collision>
				<geometry>
		      <mesh filename="package://tr2_description/meshes/stl/link_b1.stl" scale="0.001 0.001 0.001"/>
				</geometry>
				<origin rpy="0 0 1.5708" />
			</collision>
			<inertial>
				<mass value="1.0"/>
				<inertia ixx="0.1" iyy="0.1" izz="0.1" ixy="0" ixz="0" iyz="0" />
			</inertial>
			<visual>
				<geometry>
		      <mesh filename="package://tr2_description/meshes/stl/link_b1.stl" scale="0.001 0.001 0.001"/>
				</geometry>
		    <material name="slate_gray">
		      <color rgba="0.2 0.2 0.2 1"/>
		    </material>
				<origin rpy="0 0 1.5708" />
			</visual>
		</link>
	</xacro:macro>

	<!-- resulting links and joints -->
	<link name="base_link">
		<collision>
			<geometry>
        <mesh filename="package://tr2_description/meshes/stl/link_b0.stl" scale="0.001 0.001 0.001"/>
			</geometry>
			<origin rpy="0 0 1.5708" />
		</collision>
		<inertial>
			<mass value="1.0"/>
			<inertia ixx="0.1" iyy="0.1" izz="0.1" ixy="0" ixz="0" iyz="0" />
		</inertial>
		<visual>
			<geometry>
        <mesh filename="package://tr2_description/meshes/stl/link_b0.stl" scale="0.001 0.001 0.001"/>
			</geometry>
      <material name="slate_gray">
        <color rgba="0.2 0.2 0.2 1"/>
      </material>
			<origin rpy="0 0 1.5708" />
		</visual>
	</link>

	<!-- resulting links and joints -->
	<link name="link_b2">
		<collision>
			<geometry>
        <mesh filename="package://tr2_description/meshes/stl/link_b2.stl" scale="0.001 0.001 0.001"/>
			</geometry>
			<origin rpy="0 0 1.5708" />
		</collision>
		<inertial>
			<mass value="1.0"/>
			<inertia ixx="0.1" iyy="0.1" izz="0.1" ixy="0" ixz="0" iyz="0" />
		</inertial>
		<visual>
			<geometry>
        <mesh filename="package://tr2_description/meshes/stl/link_b2.stl" scale="0.001 0.001 0.001"/>
			</geometry>
      <material name="slate_gray">
        <color rgba="0.2 0.2 0.2 1"/>
      </material>
			<origin rpy="0 0 1.5708" />
		</visual>
	</link>

	<link name="link_b3">
		<collision>
			<geometry>
        <mesh filename="package://tr2_description/meshes/stl/link_b3.stl" scale="0.001 0.001 0.001"/>
			</geometry>
			<origin rpy="0 0 1.5708" />
		</collision>
		<inertial>
			<mass value="1.0"/>
			<inertia ixx="0.1" iyy="0.1" izz="0.1" ixy="0" ixz="0" iyz="0" />
		</inertial>
		<visual>
			<geometry>
        <mesh filename="package://tr2_description/meshes/stl/link_b3.stl" scale="0.001 0.001 0.001"/>
			</geometry>
      <material name="slate_gray">
        <color rgba="0.2 0.2 0.2 1"/>
      </material>
			<origin rpy="0 0 1.5708" />
		</visual>
	</link>

	<joint name="b2" type="continuous">
		<parent link="base_link"/>
		<child link="link_b2"/>
		<origin xyz="0 -0.1960 0" rpy="0 3.1415 -1.5708"/>
    <axis xyz="0 0 1"/>
		<limit effort="1.0" lower="-1.8" upper="1.8" velocity="0.2932"/>
    <dynamics damping="0.1" friction="0.1"/>
	</joint>

	<joint name="b3" type="continuous">
		<parent link="link_b2"/>
		<child link="link_b3"/>
		<origin xyz="-0.0138 0 0.0390" rpy="1.5708 0 0"/>
    <axis xyz="0 0 1"/>
		<limit effort="1.0" lower="-1.8" upper="1.8" velocity="0.2932"/>
    <dynamics damping="0.1" friction="0.1"/>
	</joint>

	<xacro:tr2_wheel name="b0l">
		<origin rpy="0 0 -1.570796" xyz="-0.3019 0.1502 0.0508"/>
	</xacro:tr2_wheel>

	<xacro:tr2_wheel name="b0r">
		<origin rpy="0 0 1.570796" xyz="0.3019 0.1502 0.0508"/>
	</xacro:tr2_wheel>

</robot>


