<?xml version="1.0"?>
<robot xmlns:xacro="http://www.ros.org/wiki/xacro">

  <xacro:include filename="$(find tr2_description)/urdf/arm/arm.macros.xacro" />
  <xacro:include filename="$(find tr2_description)/urdf/arm/arm.gazebo.xacro" />
	<xacro:include filename="$(find tr2_description)/urdf/arm/arm.transmission.xacro" />

	<xacro:arm_link name="a0" origin_rpy="3.1415 0.0000 1.5708" />
	<xacro:arm_link name="a1" origin_rpy="1.5708 1.5708 0.0000" />
	<xacro:arm_link name="a2" origin_rpy="1.5708 0.0000 -1.5708" />
	<xacro:arm_link name="a3" origin_rpy="1.5708 1.5708 0.0000" />
	<xacro:arm_link name="g0" origin_rpy="1.5708 0.0000 -1.5708" />
	<xacro:arm_link name="g1" origin_rpy="1.5708 -1.5708 0.0000" />
	<xacro:arm_link name="g1_b" origin_rpy="1.5708 -1.5708 0.0000" />

	<joint name="a0" type="revolute">
		<parent link="base_link"/>
		<child link="link_a0"/>
		<origin xyz="0.0933 0.1282 0.7292" rpy="0 3.1415 -1.5708"/>
    <axis xyz="0 0 1"/>
		<limit effort="1.0" lower="-15" upper="15" velocity="0.42"/>
    <dynamics damping="0.1" friction="0.1"/>
	</joint>

	<joint name="a1" type="revolute">
		<parent link="link_a0"/>
		<child link="link_a1"/>
		<origin xyz="0.2146 0.0800 -0.0897" rpy="0 3.1415 3.1415"/>
    <axis xyz="0 1 0"/>
		<limit effort="1.0" lower="-15" upper="15" velocity="0.42"/>
    <dynamics damping="0.1" friction="0.1"/>
	</joint>

	<joint name="a2" type="revolute">
		<parent link="link_a1"/>
		<child link="link_a2"/>
		<origin xyz="0.1669 -0.1097 0" rpy="3.1415 3.1415 0"/>
    <axis xyz="1 0 0"/>
		<limit effort="1.0" lower="-15" upper="15" velocity="0.42"/>
    <dynamics damping="0.1" friction="0.1"/>
	</joint>

	<joint name="a3" type="revolute">
		<parent link="link_a2"/>
		<child link="link_a3"/>
		<origin xyz="-0.1544 -0.0800 0" rpy="0 3.1415 0"/>
    <axis xyz="0 1 0"/>
		<limit effort="1.0" lower="-15" upper="15" velocity="0.42"/>
    <dynamics damping="0.1" friction="0.1"/>
	</joint>

	<joint name="a4" type="revolute">
		<parent link="link_a3"/>
		<child link="link_g0"/>
		<origin xyz="0.1669 -0.1097 0" rpy="0 3.1415 0"/>
    <axis xyz="1 0 0"/>
		<limit effort="1.0" lower="-15" upper="15" velocity="0.42"/>
    <dynamics damping="0.1" friction="0.1"/>
	</joint>

	<joint name="g0" type="prismatic">
		<parent link="link_g0"/>
		<child link="link_g1"/>
		<origin rpy="0 0 0" xyz="-0.135 0.0075 0"/>
    <axis xyz="0 1 0"/>
		<limit effort="1.0" lower="0" upper="0.041" velocity="0.5"/>
    <dynamics damping="0.1" friction="0.1"/>
	</joint>

	<joint name="g0_b" type="prismatic">
		<parent link="link_g0"/>
		<child link="link_g1_b"/>
		<origin rpy="0 0 0" xyz="-0.135 -0.0075 0"/>
    <axis xyz="0 1 0"/>
		<limit effort="1.0" lower="-0.041" upper="0" velocity="0.5"/>
    <dynamics damping="0.1" friction="0.1"/>
	</joint>

</robot>


