<?xml version="1.0"?>
<robot xmlns:xacro="http://www.ros.org/wiki/xacro">

  <xacro:include filename="$(find tr2_description)/urdf/head/head.gazebo.xacro" />
	<xacro:include filename="$(find tr2_description)/urdf/head/head.transmission.xacro" />

	<link name="neck_link">
		<collision>
			<geometry>
        <mesh filename="package://tr2_description/meshes/stl/link_h0.stl" scale="0.001 0.001 0.001"/>
			</geometry>
			<origin rpy="3.1415 3.1415 0"/>
		</collision>
		<inertial>
			<mass value="0.005"/>
			<inertia ixx="0.001" iyy="0.001" izz="0.001" ixy="0" ixz="0" iyz="0" />
		</inertial>
		<visual>
			<geometry>
        <mesh filename="package://tr2_description/meshes/stl/link_h0.stl" scale="0.001 0.001 0.001"/>
			</geometry>
	    <material name="slate_gray">
	      <color rgba="0.2 0.2 0.2 1"/>
	    </material>
			<origin rpy="3.1415 3.1415 0"/>
		</visual>
	</link>

	<link name="head_link">
		<collision>
			<geometry>
        <mesh filename="package://tr2_description/meshes/stl/link_h1.stl" scale="0.001 0.001 0.001"/>
			</geometry>
			<origin rpy="0 3.1415 0"/>
		</collision>
		<inertial>
			<mass value="0.005"/>
			<inertia ixx="0.001" iyy="0.001" izz="0.001" ixy="0" ixz="0" iyz="0" />
		</inertial>
		<visual>
			<geometry>
        <mesh filename="package://tr2_description/meshes/stl/link_h1.stl" scale="0.001 0.001 0.001"/>
			</geometry>
	    <material name="slate_gray">
	      <color rgba="0.2 0.2 0.2 1"/>
	    </material>
			<origin rpy="0 3.1415 0"/>
		</visual>
	</link>

  <link name="camera_link">
    <collision>
      <origin xyz="0 0 0" rpy="0 0 0" />
      <geometry>
				<box size="0.01 0.01 0.01" />
      </geometry>
    </collision>
    <inertial>
      <mass value="0.00001" />
      <inertia ixx="0.0001" ixy="0" ixz="0" iyy="0.0001" iyz="0" izz="0.0001" />
    </inertial>
  </link>

	<joint name="camera_joint" type="fixed">
		<parent link="head_link"/>
		<child link="camera_link"/>
		<origin rpy="0 0 1.5708" xyz="0.025 0.150 0.0"/>
		<axis xyz="1 0 0" />
	</joint>

	<joint name="h0" type="revolute">
		<parent link="base_link"/>
		<child link="neck_link"/>
		<origin xyz="0 -0.1227 0.9071"/>
    <axis xyz="0 0 1"/>
		<limit effort="1.0" lower="-6.29" upper="6.29" velocity="1.4661"/>
    <dynamics damping="0.1" friction="0.1"/>
	</joint>

	<joint name="h1" type="revolute">
		<parent link="neck_link"/>
		<child link="head_link"/>
		<origin xyz="-0.0688 0.1745 0.1614" rpy="-0.3490 0 0"/>
    <axis xyz="1 0 0"/>
		<limit effort="1.0" lower="-6.29" upper="6.29" velocity="1.4661"/>
    <dynamics damping="0.1" friction="0.1"/>
	</joint>

</robot>


